<?xml version="1.0"?>
<robot name="my_sphere">

  <material name="blue">
    <color rgba="0 0 0.8 1"/>
  </material>
  <material name="black">
    <color rgba="0 0 0 1"/>
  </material>
  <material name="white">
    <color rgba="1 1 1 1"/>
  </material>

  <link name="base_link">
    <visual>
      <geometry>
        <sphere radius="0.2"/>
      </geometry>
      <material name="white"/>
    </visual>
    <collision>
      <geometry>
        <sphere radius="0.2"/>
      </geometry>
    </collision>
    <inertial>
      <mass value="20"/>
      <inertia ixx="0.54" ixy="0.0" ixz="0.0" iyy="0.54" iyz="0.0" izz="0.54"/>
    </inertial>
  </link>
  <joint name="base_to_link2" type="fixed">
    <axis xyz="0 1 0" />
    <limit effort="1000.0" lower="0.0" upper="0.15" velocity="0.5"/>
    <parent link="base_link"/>
    <child link="link2"/>
    <origin xyz="0 0.2 0"/>
  </joint>
  <link name="link2">
    <visual>
      <origin xyz="0 0.1 0"/>
      <geometry>
        <box size="0.05 0.2 0.05"/>
      </geometry>
      <material name="blue"/>
    </visual>
    <collision>
      <geometry>
        <box size="0.05 0.2 0.05"/>
      </geometry>
    </collision>
    <inertial>
      <mass value="2"/>
      <inertia ixx="0.028" ixy="0.0" ixz="0.0" iyy="0.00336" iyz="0.0" izz="0.028"/>
    </inertial>
  </link>


  <joint name="base_to_link3" type="continuous">
    <axis xyz="0 0 1" />
    <parent link="base_link"/>
    <child link="link3"/>
    <origin xyz="0 -0.2 0"/>
  </joint>
  <link name="link3">
    <visual>
      <origin rpy="1.57075 0 0" xyz="0 0 0.1"/>
      <geometry>
        <box size="0.05 0.2 0.05"/>
      </geometry>
      <material name="blue"/>
    </visual>
     <collision>
      <geometry>
        <box size="0.05 0.2 0.05"/>
      </geometry>
    </collision>
    <inertial>
      <mass value="1"/>
      <inertia ixx="0.0035" ixy="0.0" ixz="0.0" iyy="0.00042" iyz="0.0" izz="0.0035"/>
    </inertial>
  </link>

  <joint name="link3_to_link4" type="revolute">
    <axis xyz="1 0 0" />
    <limit effort="1000.0" lower="-0.5" upper="0.548" velocity="0.5"/>
    <parent link="link3"/>
    <child link="link4"/>
    <origin xyz="0 0 0.2"/>
  </joint>
  <link name="link4">
    <visual>
      <origin rpy="0 1.57075 1.57075" xyz="0 0 0"/>
      <geometry>
        <box size="0.05 0.2 0.05"/>
      </geometry>
      <material name="black"/>
    </visual>
    <collision>
      <geometry>
        <box size="0.05 0.2 0.05"/>
      </geometry>
    </collision>
    <inertial>
      <mass value="1"/>
      <inertia ixx="0.014" ixy="0.0" ixz="0.0" iyy="0.00168" iyz="0.0" izz="0.014"/>
    </inertial>
  </link>

  <!-- Gazebo plugin for ROS Control -->
  <gazebo>
    <plugin name="gazebo_ros_control" filename="libgazebo_ros_control.so">
      <robotNamespace>/</robotNamespace>
    </plugin>
  </gazebo>

</robot>



